<?xml version="1.0"?>
<robot name="swarm_robot" xmlns:xacro="http://www.ros.org/wiki/xacro">
  <xacro:arg name="namespace" default=""/>
  
  <!-- Robot Parameters -->
  <xacro:property name="base_radius" value="0.25"/>
  <xacro:property name="base_height" value="0.15"/>
  <xacro:property name="wheel_radius" value="0.05"/>
  <xacro:property name="wheel_width" value="0.04"/>
  <xacro:property name="wheel_separation" value="0.4"/>
  <xacro:property name="lidar_height" value="0.10"/>
  
  <!-- Base Link -->
  <link name="base_footprint"/>
  
  <link name="base_link">
    <visual>
      <geometry>
        <cylinder radius="${base_radius}" length="${base_height}"/>
      </geometry>
      <material name="blue">
        <color rgba="0.2 0.2 0.8 1.0"/>
      </material>
    </visual>
    <collision>
      <geometry>
        <cylinder radius="${base_radius}" length="${base_height}"/>
      </geometry>
    </collision>
    <inertial>
      <mass value="10.0"/>
      <inertia ixx="0.1" ixy="0.0" ixz="0.0" iyy="0.1" iyz="0.0" izz="0.1"/>
    </inertial>
  </link>
  
  <joint name="base_footprint_joint" type="fixed">
    <parent link="base_footprint"/>
    <child link="base_link"/>
    <origin xyz="0 0 ${wheel_radius}" rpy="0 0 0"/>
  </joint>
  
  <!-- Left Wheel -->
  <link name="left_wheel">
    <visual>
      <geometry>
        <cylinder radius="${wheel_radius}" length="${wheel_width}"/>
      </geometry>
      <origin xyz="0 0 0" rpy="1.5708 0 0"/>
      <material name="black">
        <color rgba="0.1 0.1 0.1 1.0"/>
      </material>
    </visual>
    <collision>
      <geometry>
        <cylinder radius="${wheel_radius}" length="${wheel_width}"/>
      </geometry>
      <origin xyz="0 0 0" rpy="1.5708 0 0"/>
    </collision>
    <inertial>
      <mass value="1.0"/>
      <inertia ixx="0.01" ixy="0.0" ixz="0.0" iyy="0.01" iyz="0.0" izz="0.01"/>
    </inertial>
  </link>
  
  <joint name="left_wheel_joint" type="continuous">
    <parent link="base_link"/>
    <child link="left_wheel"/>
    <origin xyz="0 ${wheel_separation/2} ${-base_height/2}" rpy="0 0 0"/>
    <axis xyz="0 1 0"/>
  </joint>
  
  <!-- Right Wheel -->
  <link name="right_wheel">
    <visual>
      <geometry>
        <cylinder radius="${wheel_radius}" length="${wheel_width}"/>
      </geometry>
      <origin xyz="0 0 0" rpy="1.5708 0 0"/>
      <material name="black">
        <color rgba="0.1 0.1 0.1 1.0"/>
      </material>
    </visual>
    <collision>
      <geometry>
        <cylinder radius="${wheel_radius}" length="${wheel_width}"/>
      </geometry>
      <origin xyz="0 0 0" rpy="1.5708 0 0"/>
    </collision>
    <inertial>
      <mass value="1.0"/>
      <inertia ixx="0.01" ixy="0.0" ixz="0.0" iyy="0.01" iyz="0.0" izz="0.01"/>
    </inertial>
  </link>
  
  <joint name="right_wheel_joint" type="continuous">
    <parent link="base_link"/>
    <child link="right_wheel"/>
    <origin xyz="0 ${-wheel_separation/2} ${-base_height/2}" rpy="0 0 0"/>
    <axis xyz="0 1 0"/>
  </joint>
  
  <!-- LiDAR Sensor -->
  <link name="laser_link">
    <visual>
      <geometry>
        <cylinder radius="0.05" length="0.04"/>
      </geometry>
      <material name="red">
        <color rgba="0.8 0.2 0.2 1.0"/>
      </material>
    </visual>
    <collision>
      <geometry>
        <cylinder radius="0.05" length="0.04"/>
      </geometry>
    </collision>
    <inertial>
      <mass value="0.5"/>
      <inertia ixx="0.001" ixy="0.0" ixz="0.0" iyy="0.001" iyz="0.0" izz="0.001"/>
    </inertial>
  </link>
  
  <joint name="laser_joint" type="fixed">
    <parent link="base_link"/>
    <child link="laser_link"/>
    <origin xyz="0 0 ${base_height/2 + lidar_height}" rpy="0 0 0"/>
  </joint>
  
  <!-- Caster Ball for 3-point stability -->
  <link name="caster_link">
    <visual>
      <geometry>
        <sphere radius="0.025"/>
      </geometry>
      <material name="black">
        <color rgba="0.1 0.1 0.1 1.0"/>
      </material>
    </visual>
    <collision>
      <geometry>
        <sphere radius="0.025"/>
      </geometry>
    </collision>
    <inertial>
      <mass value="0.1"/>
      <inertia ixx="0.0001" ixy="0.0" ixz="0.0" iyy="0.0001" iyz="0.0" izz="0.0001"/>
    </inertial>
  </link>
  
  <joint name="caster_joint" type="fixed">
    <parent link="base_link"/>
    <child link="caster_link"/>
    <origin xyz="${-base_radius + 0.05} 0 ${-base_height/2 - 0.025}" rpy="0 0 0"/>
  </joint>
  
  <!-- Gazebo Plugins (Ignition Gazebo Fortress / ignition-gazebo6) -->
  <gazebo>
    <plugin filename="ignition-gazebo-diff-drive-system" name="ignition::gazebo::systems::DiffDrive">
      <left_joint>left_wheel_joint</left_joint>
      <right_joint>right_wheel_joint</right_joint>
      <wheel_separation>0.4</wheel_separation>
      <wheel_radius>0.05</wheel_radius>
      <odom_publish_frequency>20</odom_publish_frequency>
      <topic>$(arg namespace)/cmd_vel</topic>
      <odom_topic>$(arg namespace)/odom</odom_topic>
      <publish_odom>true</publish_odom>
      <publish_odom_tf>false</publish_odom_tf>
      <frame_id>$(arg namespace)/odom</frame_id>
      <child_frame_id>$(arg namespace)/base_footprint</child_frame_id>
    </plugin>
    
    <plugin filename="ignition-gazebo-odometry-publisher-system" name="ignition::gazebo::systems::OdometryPublisher">
      <odom_frame>$(arg namespace)/odom</odom_frame>
      <robot_base_frame>$(arg namespace)/base_footprint</robot_base_frame>
      <odom_topic>$(arg namespace)/odom_dummy</odom_topic>
      <tf_topic>/model/$(arg namespace)/tf</tf_topic>
      <dimensions>2</dimensions>
      <odom_publish_frequency>20</odom_publish_frequency>
    </plugin>

  </gazebo>
  
  <gazebo>
    <plugin filename="ignition-gazebo-joint-state-publisher-system" name="ignition::gazebo::systems::JointStatePublisher">
      <joint_name>left_wheel_joint</joint_name>
      <joint_name>right_wheel_joint</joint_name>
    </plugin>
  </gazebo>
  
  <gazebo reference="laser_link">
    <sensor name="laser_sensor" type="gpu_lidar">
      <topic>$(arg namespace)/scan</topic>
      <gz_frame_id>$(arg namespace)/laser_link</gz_frame_id>
      <update_rate>10.0</update_rate>
      <lidar>
        <scan>
          <horizontal>
            <samples>360</samples>
            <resolution>1.0</resolution>
            <min_angle>-3.14159</min_angle>
            <max_angle>3.14159</max_angle>
          </horizontal>
        </scan>
        <range>
          <min>0.12</min>
          <max>12.0</max>
          <resolution>0.01</resolution>
        </range>
        <noise>
          <type>gaussian</type>
          <mean>0.0</mean>
          <stddev>0.01</stddev>
        </noise>
      </lidar>
      <always_on>true</always_on>
      <visualize>false</visualize>
    </sensor>
  </gazebo>
  
  <gazebo reference="base_link">
    <material>Gazebo/Blue</material>
  </gazebo>
  
  <gazebo reference="left_wheel">
    <material>Gazebo/Black</material>
  </gazebo>
  
  <gazebo reference="right_wheel">
    <material>Gazebo/Black</material>
  </gazebo>
  
  <gazebo reference="laser_link">
    <material>Gazebo/Red</material>
  </gazebo>
  
</robot>
